<?xml version="1.0" encoding="UTF-8"?>
<!-- Generated by org.testng.reporters.JUnitReportReporter -->
<testsuite hostname="yasassri-device" name="org.wso2.carbon.tests.Example1" tests="10" failures="1" timestamp="31 Mar 2016 12:16:34 GMT" time="0.007" errors="1">
  <testcase name="testMethod4" time="0.001" classname="org.wso2.carbon.tests.Example1"/>
  <testcase name="testMethod5" time="0.002" classname="org.wso2.carbon.tests.Example1"/>
  <testcase name="testMethod1" time="0.001" classname="org.wso2.carbon.tests.Example1">
    <failure type="java.lang.AssertionError">
      <![CDATA[java.lang.AssertionError
	at org.wso2.carbon.tests.Example1.testMethod1(Example1.java:49)
	at sun.reflect.NativeMethodAccessorImpl.invoke0(Native Method)
	at sun.reflect.NativeMethodAccessorImpl.invoke(NativeMethodAccessorImpl.java:62)
	at sun.reflect.DelegatingMethodAccessorImpl.invoke(DelegatingMethodAccessorImpl.java:43)
	at java.lang.reflect.Method.invoke(Method.java:498)
	at org.testng.internal.MethodInvocationHelper.invokeMethod(MethodInvocationHelper.java:85)
	at org.testng.internal.Invoker.invokeMethod(Invoker.java:639)
	at org.testng.internal.Invoker.invokeTestMethod(Invoker.java:816)
	at org.testng.internal.Invoker.invokeTestMethods(Invoker.java:1124)
	at org.testng.internal.TestMethodWorker.invokeTestMethods(TestMethodWorker.java:125)
	at org.testng.internal.TestMethodWorker.run(TestMethodWorker.java:108)
	at org.testng.TestRunner.privateRun(TestRunner.java:774)
	at org.testng.TestRunner.run(TestRunner.java:624)
	at org.testng.SuiteRunner.runTest(SuiteRunner.java:359)
	at org.testng.SuiteRunner.runSequentially(SuiteRunner.java:354)
	at org.testng.SuiteRunner.privateRun(SuiteRunner.java:312)
	at org.testng.SuiteRunner.run(SuiteRunner.java:261)
	at org.testng.SuiteRunnerWorker.runSuite(SuiteRunnerWorker.java:52)
	at org.testng.SuiteRunnerWorker.run(SuiteRunnerWorker.java:86)
	at org.testng.TestNG.runSuitesSequentially(TestNG.java:1191)
	at org.testng.TestNG.runSuitesLocally(TestNG.java:1116)
	at org.testng.TestNG.run(TestNG.java:1024)
	at org.apache.maven.surefire.testng.TestNGExecutor.run(TestNGExecutor.java:281)
	at org.apache.maven.surefire.testng.TestNGXmlTestSuite.execute(TestNGXmlTestSuite.java:75)
	at org.apache.maven.surefire.testng.TestNGProvider.invoke(TestNGProvider.java:121)
	at org.apache.maven.surefire.booter.ForkedBooter.invokeProviderInSameClassLoader(ForkedBooter.java:290)
	at org.apache.maven.surefire.booter.ForkedBooter.runSuitesInProcess(ForkedBooter.java:242)
	at org.apache.maven.surefire.booter.ForkedBooter.main(ForkedBooter.java:121)
]]>
    </failure>
  </testcase> <!-- testMethod1 -->
  <testcase name="testMethod2" time="0.001" classname="org.wso2.carbon.tests.Example1">
    <error type="java.lang.Throwable" message="Method Example1.testMethod2()[pri:0, instance:org.wso2.carbon.tests.Example1@6b71769e] depends on not successfully finished methods">
      <![CDATA[java.lang.Throwable: Method Example1.testMethod2()[pri:0, instance:org.wso2.carbon.tests.Example1@6b71769e] depends on not successfully finished methods
	at org.testng.internal.Invoker.invokeTestMethods(Invoker.java:1033)
	at org.testng.internal.TestMethodWorker.invokeTestMethods(TestMethodWorker.java:125)
	at org.testng.internal.TestMethodWorker.run(TestMethodWorker.java:108)
	at org.testng.TestRunner.privateRun(TestRunner.java:774)
	at org.testng.TestRunner.run(TestRunner.java:624)
	at org.testng.SuiteRunner.runTest(SuiteRunner.java:359)
	at org.testng.SuiteRunner.runSequentially(SuiteRunner.java:354)
	at org.testng.SuiteRunner.privateRun(SuiteRunner.java:312)
	at org.testng.SuiteRunner.run(SuiteRunner.java:261)
	at org.testng.SuiteRunnerWorker.runSuite(SuiteRunnerWorker.java:52)
	at org.testng.SuiteRunnerWorker.run(SuiteRunnerWorker.java:86)
	at org.testng.TestNG.runSuitesSequentially(TestNG.java:1191)
	at org.testng.TestNG.runSuitesLocally(TestNG.java:1116)
	at org.testng.TestNG.run(TestNG.java:1024)
	at org.apache.maven.surefire.testng.TestNGExecutor.run(TestNGExecutor.java:281)
	at org.apache.maven.surefire.testng.TestNGXmlTestSuite.execute(TestNGXmlTestSuite.java:75)
	at org.apache.maven.surefire.testng.TestNGProvider.invoke(TestNGProvider.java:121)
	at org.apache.maven.surefire.booter.ForkedBooter.invokeProviderInSameClassLoader(ForkedBooter.java:290)
	at org.apache.maven.surefire.booter.ForkedBooter.runSuitesInProcess(ForkedBooter.java:242)
	at org.apache.maven.surefire.booter.ForkedBooter.main(ForkedBooter.java:121)
]]>
    </error>
  </testcase> <!-- testMethod2 -->
  <testcase name="testMethod4" time="0.000" classname="org.wso2.carbon.tests.Example1"/>
  <testcase name="testMethod4" time="0.000" classname="org.wso2.carbon.tests.Example1"/>
  <testcase name="testMethod6" time="0.000" classname="org.wso2.carbon.tests.Example1"/>
  <testcase name="testMethod3" time="0.000" classname="org.wso2.carbon.tests.Example1"/>
  <testcase name="testMethod6" time="0.000" classname="org.wso2.carbon.tests.Example1"/>
  <testcase name="testMethod6" time="0.002" classname="org.wso2.carbon.tests.Example1"/>
</testsuite> <!-- org.wso2.carbon.tests.Example1 -->
